Workbook

Sheet ООО
A1: № | B1: Клиенты | C1: Дата счета | D1: Сумма договра | E1: Дата опалты | F1: Предоплата | G1: Долг клиента | H1: Дата опалты | I1: Внесённая сумма | J1: Подписанные акты | K1: НДС | L1: Сумма | M1: Сумма поступлений | N1: =SUM(F:F,I:I) -> 0 | O1: Чистый приход | P1: =SUM(L:L) -> #DIV/0! | Q1: Сумма долга | R1: =SUM(G:G) -> 0 | S1: Сумма выставленная | T1: =SUM(D:D) -> 0 | U1: Комметраий
A2: 1 | G2: =D2-F2-I2 -> 0 | K2: 1.2 | L2: =D2/K2 -> 0
A3: 2 | G3: =D3-F3-I3 -> 0 | K3: 1.2 | L3: =D3/K3 -> 0
A4: 3 | G4: =D4-F4-I4 -> 0 | K4: 1.2 | L4: =D4/K4 -> 0
A5: 4 | G5: =D5-F5-I5 -> 0 | K5: 1.2 | L5: =D5/K5 -> 0
A6: 5 | G6: =D6-F6-I6 -> 0 | K6: 1.2 | L6: =D6/K6 -> 0
A7: 6 | G7: =D7-F7-I7 -> 0 | K7: 1.2 | L7: =D7/K7 -> 0
A8: 7 | G8: =D8-F8-I8 -> 0 | K8: 1.2 | L8: =D8/K8 -> 0
A9: 8 | G9: =D9-F9-I9 -> 0 | K9: 1.2 | L9: =D9/K9 -> 0
A10: 9 | G10: =D10-F10-I10 -> 0 | K10: 1.2 | L10: =D10/K10 -> 0
A11: 10 | G11: =D11-F11-I11 -> 0 | K11: 1.2 | L11: =D11/K11 -> 0
A12: 11 | G12: =D12-F12-I12 -> 0 | K12: 1.2 | L12: =D12/K12 -> 0
A13: 12 | G13: =D13-F13-I13 -> 0 | K13: 1.2 | L13: =D13/K13 -> 0
... A29: 28 | G29: =D29-F29-I29 -> 0 | K29: 1.2 | L29: =D29/K29 -> 0
A30: 29 | G30: =D30-F30-I30 -> 0 | L30: =D30/K30 -> #DIV/0!
A31: 30 | G31: =D31-F31-I31 -> 0 | L31: =D31/K31 -> #DIV/0!
A32: 31 | G32: =D32-F32-I32 -> 0 | L32: =D32/K32 -> #DIV/0!
A33: 32 | G33: =D33-F33-I33 -> 0 | L33: =D33/K33 -> #DIV/0!
A34: 33 | G34: =D34-F34-I34 -> 0 | L34: =D34/K34 -> #DIV/0!
A35: 34 | G35: =D35-F35-I35 -> 0 | L35: =D35/K35 -> #DIV/0!
A36: 35 | G36: =D36-F36-I36 -> 0 | L36: =D36/K36 -> #DIV/0!
A37: 36 | G37: =D37-F37-I37 -> 0 | L37: =D37/K37 -> #DIV/0!
A38: 37 | G38: =D38-F38-I38 -> 0 | L38: =D38/K38 -> #DIV/0!
A39: 38 | G39: =D39-F39-I39 -> 0 | L39: =D39/K39 -> #DIV/0!
A40: 39 | G40: =D40-F40-I40 -> 0 | L40: =D40/K40 -> #DIV/0!
A41: 40 | G41: =D41-F41-I41 -> 0 | L41: =D41/K41 -> #DIV/0!
... A64: 63 | G64: =D64-F64-I64 -> 0 | L64: =D64/K64 -> #DIV/0!
A65: /1 | G65: =D65-F65-I65 -> 0 | L65: =D65/K65 -> #DIV/0!
A66: 64 | G66: =D66-F66-I66 -> 0 | L66: =D66/K66 -> #DIV/0!
A67: 65 | G67: =D67-F67-I67 -> 0 | L67: =D67/K67 -> #DIV/0!
A68: 66 | G68: 0 | L68: =D68/K68 -> #DIV/0!
A69: 67 | G69: =D69-F69-I69 -> 0 | L69: =D69/K69 -> #DIV/0!
A70: 68 | G70: =D70-F70-I70 -> 0 | L70: =D70/K70 -> #DIV/0!
A71: 69 | G71: =D71-F71-I71 -> 0 | L71: =D71/K71 -> #DIV/0!
A72: 70 | G72: =D72-F72-I72 -> 0 | L72: =D72/K72 -> #DIV/0!
A73: 71/3 | G73: =D73-F73-I73 -> 0 | L73: =D73/K73 -> #DIV/0!
A74: 72 | G74: =D74-F74-I74 -> 0 | L74: =D74/K74 -> #DIV/0!
A75: 73/4 | G75: =D75-F75-I75 -> 0 | L75: =D75/K75 -> #DIV/0!
A76: 74/6 | G76: =D76-F76-I76 -> 0 | L76: =D76/K76 -> #DIV/0!
A77: 75 | G77: =D77-F77-I77 -> 0 | L77: =D77/K77 -> #DIV/0!
...

Sheet Ип
A1: № | B1: Клиенты | C1: Дата счета | D1: Сумма договра | E1: Дата опалты | F1: Предоплата | G1: Долг клиента | H1: Дата опалты | I1: Внесённая сумма | J1: Налог | K1: Сумма | L1: Сумма поступлений | M1: =SUM(F:F,I:I) -> 110000 | N1: Сумма долга | O1: =SUM(G:G) -> 0 | P1: Сумма выставленная | Q1: =SUM(D:D) -> 110000 | R1: Налог | S1: =M1/1.06-SUM(D:D) -> -6226.4151
A2: 1 | B2: ИП Романова | D2: 110000 | F2: 110000 | G2: =D2-F2-I2 -> 0 | K2: =F2+I2 -> 110000 | R2: ИП Завгородний
A3: 2 | G3: =D3-F3-I3 -> 0 | K3: =F3+I3 -> 0 | R3: ИП Завгородний
A4: 3 | G4: =D4-F4-I4 -> 0 | K4: =F4+I4 -> 0 | R4: ИП Завгородний
A5: 4 | G5: =D5-F5-I5 -> 0 | K5: =F5+I5 -> 0 | R5: ИП Завгородний
A6: 5 | G6: =D6-F6-I6 -> 0 | K6: =F6+I6 -> 0 | R6: ИП Завгородний
A7: 6 | G7: =D7-F7-I7 -> 0 | K7: =F7+I7 -> 0 | R7: ИП Завгородний
A8: 7 | G8: =D8-F8-I8 -> 0 | K8: =F8+I8 -> 0 | R8: ИП Завгородний
A9: 8 | G9: =D9-F9-I9 -> 0 | K9: =F9+I9 -> 0 | R9: ИП Завгородний
A10: 9 | G10: =D10-F10-I10 -> 0 | K10: =F10+I10 -> 0 | R10: ИП Завгородний
A11: 10 | G11: =D11-F11-I11 -> 0 | K11: =F11+I11 -> 0 | R11: ИП Завгородний
A12: 11 | G12: =D12-F12-I12 -> 0 | K12: =F12+I12 -> 0 | R12: ИП Завгородний
A13: 12 | G13: =D13-F13-I13 -> 0 | K13: =F13+I13 -> 0 | R13: ИП Завгородний
A14: 13 | G14: =D14-F14-I14 -> 0 | K14: =F14+I14 -> 0 | R14: ИП Завгородний
... A64: 63 | G64: =D64-F64-I64 -> 0 | K64: =F64+I64 -> 0 | R64: ИП Завгородний
A65: /1 | G65: =D65-F65-I65 -> 0 | K65: =F65+I65 -> 0 | R65: ООО ТК МВЛ
A66: 64 | G66: =D66-F66-I66 -> 0 | K66: =F66+I66 -> 0 | R66: ИП Завгородний
A67: 65 | G67: =D67-F67-I67 -> 0 | K67: =F67+I67 -> 0 | R67: ИП Завгородний
A68: 66 | G68: 0 | K68: =F68+I68 -> 0 | R68: ИП Завгородний
A69: 67 | G69: =D69-F69-I69 -> 0 | K69: =F69+I69 -> 0 | R69: ИП Завгородний
A70: 68 | G70: =D70-F70-I70 -> 0 | K70: =F70+I70 -> 0 | R70: ИП Завгородний
A71: 69 | G71: =D71-F71-I71 -> 0 | K71: =F71+I71 -> 0 | R71: ИП Завгородний
A72: 70 | G72: =D72-F72-I72 -> 0 | K72: =F72+I72 -> 0 | R72: ИП Завгородний
A73: 71/3 | G73: =D73-F73-I73 -> 0 | K73: =F73+I73 -> 0 | R73: ООО ТК МВЛ
A74: 72 | G74: =D74-F74-I74 -> 0 | K74: =F74+I74 -> 0 | R74: ИП Завгородний
A75: 73/4 | G75: =D75-F75-I75 -> 0 | K75: =F75+I75 -> 0 | R75: ООО ТК МВЛ
A76: 74/6 | G76: =D76-F76-I76 -> 0 | K76: =F76+I76 -> 0 | R76: ООО ТК МВЛ
A77: 75 | G77: =D77-F77-I77 -> 0 | K77: =F77+I77 -> 0 | R77: ИП Завгородний
A78: 76/5 | G78: =D78-F78-I78 -> 0 | K78: =F78+I78 -> 0 | R78: ООО ТК МВЛ
A79: 77 | G79: =D79-F79-I79 -> 0 | K79: =F79+I79 -> 0 | R79: ИП Завгородний
A80: 78 | G80: =D80-F80-I80 -> 0 | K80: =F80+I80 -> 0 | R80: ИП Завгородний
A81: 79 | G81: =D81-F81-I81 -> 0 | K81: =F81+I81 -> 0 | R81: ИП Завгородний
A82: 80 | G82: =D82-F82-I82 -> 0 | K82: =F82+I82 -> 0 | R82: ИП Завгородний
A83: 81 | G83: =D83-F83-I83 -> 0 | K83: =F83+I83 -> 0 | R83: ИП Завгородний
A84: 82 | G84: =D84-F84-I84 -> 0 | K84: =F84+I84 -> 0 | R84: ИП Завгородний
A85: 83 | G85: =D85-F85-I85 -> 0 | K85: =F85+I85 -> 0 | R85: ИП Завгородний
A86: 84 | G86: =D86-F86-I86 -> 0 | K86: =F86+I86 -> 0 | R86: ИП Завгородний
A87: 85 | G87: =D87-F87-I87 -> 0 | K87: =F87+I87 -> 0 | R87: ИП Завгородний
A88: 86 | G88: =D88-F88-I88 -> 0 | K88: =F88+I88 -> 0 | R88: ИП Завгородний
A89: 87/7 | G89: =D89-F89-I89 -> 0 | K89: =F89+I89 -> 0 | R89: ООО ТК МВЛ
...

Sheet Наличка
A1: Физ лица | B1: Физ дата | C1: Сумма | D1: дата оплаты | E1: сумма поступления | F1: долг | G1: Общая сумма | H1: =SUM(E:E) -> 0 | I1: Общий долг | J1: =SUM(F:F) -> 0
F2: =C2-E2 -> 0
F3: =C3-E3 -> 0
F4: =C4-E4 -> 0
F5: =C5-E5 -> 0
F6: =C6-E6 -> 0
F7: =C7-E7 -> 0
F8: =C8-E8 -> 0
F9: =C9-E9 -> 0
F10: =C10-E10 -> 0
F11: =C11-E11 -> 0
F12: =C12-E12 -> 0
F13: =C13-E13 -> 0
... F53: =C53-E53 -> 0

Sheet Расходы на перевозки
A1: № | B1: Клиенты | C1: Дата Перевозки | D1: Сумма договра | E1: Сумма НДС | F1: Перевозчики | G1: Расход на Фуру | H1: дата оплаты фуры | I1: Расход на склад | J1: % | K1: минус% | L1: Расход авто город | M1: % | N1: минус% | O1: Прочие расходы | P1: % | Q1: минус% | R1: Штрафы | S1: % | T1: минус% | U1: дата оплаты расходов | V1: Чистая прибыль | W1: Общие расходы | X1: Дельта Прибыль | Y1: =SUM(V:V) -> 103773 | Z1: Затраты | AA1: =SUM(W:W) -> 0 | AB1: Оборот | AC1: =SUM(D:D)+SUM(E:E) -> 103773 | AD1: Оплаченные суммы фуры | AE1: =SUM(G:G) -> 0 | AF1: Оплаченные суммы пр. расходы | AG1: =SUM(K:K)+SUM(N:N)+SUM(Q:Q)+SUM(T:T) -> 0
A2: 1 | B2: ИП Романова | C2: 45901 | D2: 103773 | J2: 1.2 | K2: =I2/J2 -> 0 | M2: 1 | N2: =L2/M2 -> 0 | P2: 1 | S2: 1 | T2: =R2/S2 -> 0 | V2: =D2+E2-G2-I2/J2-L2/M2-O2/P2-R2/S2 -> 103773 | W2: =G2+I2/J2+L2/M2+O2/P2+R2/S2 -> 0
A3: 2 | J3: 1.2 | K3: =I3/J3 -> 0 | M3: 1 | N3: =L3/M3 -> 0 | P3: 1 | Q3: =O3/P3 -> 0 | S3: 1 | T3: =R3/S3 -> 0 | V3: =D3+E3-G3-I3/J3-L3/M3-O3/P3-R3/S3 -> 0 | W3: =G3+I3/J3+L3/M3+O3/P3+R3/S3 -> 0
A4: 2 | J4: 1.2 | K4: =I4/J4 -> 0 | M4: 1 | N4: =L4/M4 -> 0 | P4: 1 | Q4: =O4/P4 -> 0 | S4: 1 | T4: =R4/S4 -> 0 | V4: =D4+E4-G4-I4/J4-L4/M4-O4/P4-R4/S4 -> 0 | W4: =G4+I4/J4+L4/M4+O4/P4+R4/S4 -> 0
A5: 2 | J5: 1 | K5: =I5/J5 -> 0 | M5: 1 | N5: =L5/M5 -> 0 | P5: 1 | Q5: =O5/P5 -> 0 | S5: 1 | T5: =R5/S5 -> 0 | V5: =D5+E5-G5-I5/J5-L5/M5-O5/P5-R5/S5 -> 0 | W5: =G5+I5/J5+L5/M5+O5/P5+R5/S5 -> 0
A6: 3 | J6: 1 | K6: =I6/J6 -> 0 | M6: 1 | N6: =L6/M6 -> 0 | P6: 1 | Q6: =O6/P6 -> 0 | S6: 1 | T6: =R6/S6 -> 0 | V6: =D6+E6-G6-I6/J6-L6/M6-O6/P6-R6/S6 -> 0 | W6: =G6+I6/J6+L6/M6+O6/P6+R6/S6 -> 0
A7: 4 | J7: 1 | K7: =I7/J7 -> 0 | M7: 1 | N7: =L7/M7 -> 0 | P7: 1 | Q7: =O7/P7 -> 0 | S7: 1 | T7: =R7/S7 -> 0 | V7: =D7+E7-G7-I7/J7-L7/M7-O7/P7-R7/S7 -> 0 | W7: =G7+I7/J7+L7/M7+O7/P7+R7/S7 -> 0
A8: 4 | J8: 1 | K8: =I8/J8 -> 0 | M8: 1 | N8: =L8/M8 -> 0 | P8: 1 | Q8: =O8/P8 -> 0 | S8: 1 | T8: =R8/S8 -> 0 | V8: =D8+E8-G8-I8/J8-L8/M8-O8/P8-R8/S8 -> 0 | W8: =G8+I8/J8+L8/M8+O8/P8+R8/S8 -> 0
A9: 5 | J9: 1 | K9: =I9/J9 -> 0 | M9: 1 | N9: =L9/M9 -> 0 | P9: 1 | Q9: =O9/P9 -> 0 | S9: 1 | T9: =R9/S9 -> 0 | V9: =D9+E9-G9-I9/J9-L9/M9-O9/P9-R9/S9 -> 0 | W9: =G9+I9/J9+L9/M9+O9/P9+R9/S9 -> 0
A10: 5 | J10: 1 | K10: =I10/J10 -> 0 | M10: 1 | N10: =L10/M10 -> 0 | P10: 1 | Q10: =O10/P10 -> 0 | S10: 1 | T10: =R10/S10 -> 0 | V10: =D10+E10-G10-I10/J10-L10/M10-O10/P10-R10/S10 -> 0 | W10: =G10+I10/J10+L10/M10+O10/P10+R10/S10 -> 0
A11: 5 | J11: 1 | K11: =I11/J11 -> 0 | M11: 1 | N11: =L11/M11 -> 0 | P11: 1 | Q11: =O11/P11 -> 0 | S11: 1 | T11: =R11/S11 -> 0 | V11: =D11+E11-G11-I11/J11-L11/M11-O11/P11-R11/S11 -> 0 | W11: =G11+I11/J11+L11/M11+O11/P11+R11/S11 -> 0
A12: 6 | J12: 1 | K12: =I12/J12 -> 0 | M12: 1 | N12: =L12/M12 -> 0 | P12: 1 | Q12: =O12/P12 -> 0 | S12: 1 | T12: =R12/S12 -> 0 | V12: =D12+E12-G12-I12/J12-L12/M12-O12/P12-R12/S12 -> 0 | W12: =G12+I12/J12+L12/M12+O12/P12+R12/S12 -> 0
A13: 6 | J13: 1 | K13: =I13/J13 -> 0 | M13: 1 | N13: =L13/M13 -> 0 | P13: 1 | Q13: =O13/P13 -> 0 | S13: 1 | T13: =R13/S13 -> 0 | V13: =D13+E13-G13-I13/J13-L13/M13-O13/P13-R13/S13 -> 0 | W13: =G13+I13/J13+L13/M13+O13/P13+R13/S13 -> 0
A14: 7 | J14: 1 | K14: =I14/J14 -> 0 | M14: 1 | N14: =L14/M14 -> 0 | P14: 1 | Q14: =O14/P14 -> 0 | S14: 1 | T14: =R14/S14 -> 0 | V14: =D14+E14-G14-I14/J14-L14/M14-O14/P14-R14/S14 -> 0 | W14: =G14+I14/J14+L14/M14+O14/P14+R14/S14 -> 0
... A20: 9 | J20: 1 | K20: =I20/J20 -> 0 | M20: 1 | N20: =L20/M20 -> 0 | P20: 1 | Q20: =O20/P20 -> 0 | S20: 1 | T20: =R20/S20 -> 0 | V20: =D20+E20-G20-I20/J20-L20/M20-O20/P20-R20/S20 -> 0 | W20: =G20+I20/J20+L20/M20+O20/P20+R20/S20 -> 0
A21: 9 4 | J21: 1 | K21: =I21/J21 -> 0 | M21: 1 | N21: =L21/M21 -> 0 | P21: 1 | Q21: =O21/P21 -> 0 | S21: 1 | T21: =R21/S21 -> 0 | V21: =D21+E21-G21-I21/J21-L21/M21-O21/P21-R21/S21 -> 0 | W21: =G21+I21/J21+L21/M21+O21/P21+R21/S21 -> 0
A22: 10 | J22: 1 | K22: =I22/J22 -> 0 | M22: 1 | N22: =L22/M22 -> 0 | P22: 1 | Q22: =O22/P22 -> 0 | S22: 1 | T22: =R22/S22 -> 0 | V22: =D22+E22-G22-I22/J22-L22/M22-O22/P22-R22/S22 -> 0 | W22: =G22+I22/J22+L22/M22+O22/P22+R22/S22 -> 0
A23: 11 | J23: 1 | K23: =I23/J23 -> 0 | M23: 1 | N23: =L23/M23 -> 0 | P23: 1 | Q23: =O23/P23 -> 0 | S23: 1 | T23: =R23/S23 -> 0 | V23: =D23+E23-G23-I23/J23-L23/M23-O23/P23-R23/S23 -> 0 | W23: =G23+I23/J23+L23/M23+O23/P23+R23/S23 -> 0
A24: 12 | J24: 1 | K24: =I24/J24 -> 0 | M24: 1 | N24: =L24/M24 -> 0 | P24: 1 | Q24: =O24/P24 -> 0 | S24: 1 | T24: =R24/S24 -> 0 | V24: =D24+E24-G24-I24/J24-L24/M24-O24/P24-R24/S24 -> 0 | W24: =G24+I24/J24+L24/M24+O24/P24+R24/S24 -> 0
A25: 13 | J25: 1 | K25: =I25/J25 -> 0 | M25: 1 | N25: =L25/M25 -> 0 | P25: 1 | Q25: =O25/P25 -> 0 | S25: 1 | T25: =R25/S25 -> 0 | V25: =D25+E25-G25-I25/J25-L25/M25-O25/P25-R25/S25 -> 0 | W25: =G25+I25/J25+L25/M25+O25/P25+R25/S25 -> 0
A26: 14 | J26: 1 | K26: =I26/J26 -> 0 | M26: 1 | N26: =L26/M26 -> 0 | P26: 1 | Q26: =O26/P26 -> 0 | S26: 1 | T26: =R26/S26 -> 0 | V26: =D26+E26-G26-I26/J26-L26/M26-O26/P26-R26/S26 -> 0 | W26: =G26+I26/J26+L26/M26+O26/P26+R26/S26 -> 0
A27: 15 | J27: 1 | K27: =I27/J27 -> 0 | M27: 1 | N27: =L27/M27 -> 0 | P27: 1 | Q27: =O27/P27 -> 0 | S27: 1 | T27: =R27/S27 -> 0 | V27: =D27+E27-G27-I27/J27-L27/M27-O27/P27-R27/S27 -> 0 | W27: =G27+I27/J27+L27/M27+O27/P27+R27/S27 -> 0
A28: 15 | J28: 1 | K28: =I28/J28 -> 0 | M28: 1 | N28: =L28/M28 -> 0 | P28: 1 | Q28: =O28/P28 -> 0 | S28: 1 | T28: =R28/S28 -> 0 | V28: =D28+E28-G28-I28/J28-L28/M28-O28/P28-R28/S28 -> 0 | W28: =G28+I28/J28+L28/M28+O28/P28+R28/S28 -> 0
A29: 16 | J29: 1 | K29: =I29/J29 -> 0 | M29: 1 | N29: =L29/M29 -> 0 | P29: 1 | Q29: =O29/P29 -> 0 | S29: 1 | T29: =R29/S29 -> 0 | V29: =D29+E29-G29-I29/J29-L29/M29-O29/P29-R29/S29 -> 0 | W29: =G29+I29/J29+L29/M29+O29/P29+R29/S29 -> 0
A30: 17 | J30: 1 | K30: =I30/J30 -> 0 | M30: 1 | N30: =L30/M30 -> 0 | P30: 1 | Q30: =O30/P30 -> 0 | S30: 1 | T30: =R30/S30 -> 0 | V30: =D30+E30-G30-I30/J30-L30/M30-O30/P30-R30/S30 -> 0 | W30: =G30+I30/J30+L30/M30+O30/P30+R30/S30 -> 0
A31: 18 | J31: 1 | K31: =I31/J31 -> 0 | M31: 1 | N31: =L31/M31 -> 0 | P31: 1 | Q31: =O31/P31 -> 0 | S31: 1 | T31: =R31/S31 -> 0 | V31: =D31+E31-G31-I31/J31-L31/M31-O31/P31-R31/S31 -> 0 | W31: =G31+I31/J31+L31/M31+O31/P31+R31/S31 -> 0
A32: 19 | J32: 1 | K32: =I32/J32 -> 0 | M32: 1 | N32: =L32/M32 -> 0 | P32: 1 | Q32: =O32/P32 -> 0 | S32: 1 | T32: =R32/S32 -> 0 | V32: =D32+E32-G32-I32/J32-L32/M32-O32/P32-R32/S32 -> 0 | W32: =G32+I32/J32+L32/M32+O32/P32+R32/S32 -> 0
A33: 19 | J33: 1 | K33: =I33/J33 -> 0 | M33: 1 | N33: =L33/M33 -> 0 | P33: 1 | Q33: =O33/P33 -> 0 | S33: 1 | T33: =R33/S33 -> 0 | V33: =D33+E33-G33-I33/J33-L33/M33-O33/P33-R33/S33 -> 0 | W33: =G33+I33/J33+L33/M33+O33/P33+R33/S33 -> 0
... A160: 86 | J160: 1 | K160: =I160/J160 -> 0 | M160: 1 | N160: =L160/M160 -> 0 | P160: 1 | Q160: =O160/P160 -> 0 | S160: 1 | T160: =R160/S160 -> 0 | V160: =D160+E160-G160-I160/J160-L160/M160-O160/P160-R160/S160 -> 0 | W160: =G160+I160/J160+L160/M160+O160/P160+R160/S160 -> 0
J161: 1 | K161: =I161/J161 -> 0 | M161: 1 | N161: =L161/M161 -> 0 | P161: 1 | Q161: =O161/P161 -> 0 | S161: 1 | T161: =R161/S161 -> 0 | V161: =D161+E161-G161-I161/J161-L161/M161-O161/P161-R161/S161 -> 0 | W161: =G161+I161/J161+L161/M161+O161/P161+R161/S161 -> 0
J162: 1 | K162: =I162/J162 -> 0 | M162: 1 | N162: =L162/M162 -> 0 | P162: 1 | Q162: =O162/P162 -> 0 | S162: 1 | T162: =R162/S162 -> 0 | V162: =D162+E162-G162-I162/J162-L162/M162-O162/P162-R162/S162 -> 0 | W162: =G162+I162/J162+L162/M162+O162/P162+R162/S162 -> 0
J163: 1 | K163: =I163/J163 -> 0 | M163: 1 | N163: =L163/M163 -> 0 | P163: 1 | Q163: =O163/P163 -> 0 | S163: 1 | T163: =R163/S163 -> 0 | V163: =D163+E163-G163-I163/J163-L163/M163-O163/P163-R163/S163 -> 0 | W163: =G163+I163/J163+L163/M163+O163/P163+R163/S163 -> 0
J164: 1 | K164: =I164/J164 -> 0 | M164: 1 | N164: =L164/M164 -> 0 | P164: 1 | Q164: =O164/P164 -> 0 | S164: 1 | T164: =R164/S164 -> 0 | V164: =D164+E164-G164-I164/J164-L164/M164-O164/P164-R164/S164 -> 0 | W164: =G164+I164/J164+L164/M164+O164/P164+R164/S164 -> 0
J165: 1 | K165: =I165/J165 -> 0 | M165: 1 | N165: =L165/M165 -> 0 | P165: 1 | Q165: =O165/P165 -> 0 | S165: 1 | T165: =R165/S165 -> 0 | V165: =D165+E165-G165-I165/J165-L165/M165-O165/P165-R165/S165 -> 0 | W165: =G165+I165/J165+L165/M165+O165/P165+R165/S165 -> 0
J166: 1 | K166: =I166/J166 -> 0 | M166: 1 | N166: =L166/M166 -> 0 | P166: 1 | Q166: =O166/P166 -> 0 | S166: 1 | T166: =R166/S166 -> 0 | V166: =D166+E166-G166-I166/J166-L166/M166-O166/P166-R166/S166 -> 0 | W166: =G166+I166/J166+L166/M166+O166/P166+R166/S166 -> 0
J167: 1 | K167: =I167/J167 -> 0 | M167: 1 | N167: =L167/M167 -> 0 | P167: 1 | Q167: =O167/P167 -> 0 | S167: 1 | T167: =R167/S167 -> 0 | V167: =D167+E167-G167-I167/J167-L167/M167-O167/P167-R167/S167 -> 0 | W167: =G167+I167/J167+L167/M167+O167/P167+R167/S167 -> 0
J168: 1 | K168: =I168/J168 -> 0 | M168: 1 | N168: =L168/M168 -> 0 | P168: 1 | Q168: =O168/P168 -> 0 | S168: 1 | T168: =R168/S168 -> 0 | V168: =D168+E168-G168-I168/J168-L168/M168-O168/P168-R168/S168 -> 0 | W168: =G168+I168/J168+L168/M168+O168/P168+R168/S168 -> 0
J169: 1 | K169: =I169/J169 -> 0 | M169: 1 | N169: =L169/M169 -> 0 | P169: 1 | Q169: =O169/P169 -> 0 | S169: 1 | T169: =R169/S169 -> 0 | V169: =D169+E169-G169-I169/J169-L169/M169-O169/P169-R169/S169 -> 0 | W169: =G169+I169/J169+L169/M169+O169/P169+R169/S169 -> 0
J170: 1 | K170: =I170/J170 -> 0 | M170: 1 | N170: =L170/M170 -> 0 | P170: 1 | Q170: =O170/P170 -> 0 | S170: 1 | T170: =R170/S170 -> 0 | V170: =D170+E170-G170-I170/J170-L170/M170-O170/P170-R170/S170 -> 0 | W170: =G170+I170/J170+L170/M170+O170/P170+R170/S170 -> 0
J171: 1 | K171: =I171/J171 -> 0 | M171: 1 | N171: =L171/M171 -> 0 | P171: 1 | Q171: =O171/P171 -> 0 | S171: 1 | T171: =R171/S171 -> 0 | V171: =D171+E171-G171-I171/J171-L171/M171-O171/P171-R171/S171 -> 0 | W171: =G171+I171/J171+L171/M171+O171/P171+R171/S171 -> 0
...

Sheet Зарплаты 
A1: Договор | B1: Дельта прибыль заявки | C1: Менеджера | D1: Зарплата | G1: Запралата за месяц
D2: =B2*0.4 -> 0 | H2: Андрей | I2: Илья | J2: Ильяс | K2: Женя | L2: Настя | M2: Ещё | N2: И Ещё
D3: =B3*0.4 -> 0 | G3: Всего | H3: =SUMIF(C:C,"Андрей", D:D) -> 0 | I3: =SUMIF(C:C,"Илья", D:D) -> 0 | J3: =SUMIF(C:C,"Ильяс", D:D) -> 0 | K3: =SUMIF(C:C,"Женя", D:D) -> 0 | L3: =SUMIF(C:C,"Настя", D:D) -> 0 | M3: =SUMIF(C:C,"Ещё", D:D) -> 0 | N3: =SUMIF(C:C,"и Ещё", D:D) -> 0
D4: =B4*0.4 -> 0 | G4: Взял
D5: =B5*0.4 -> 0 | G5: Остатки | H5: =H3-H4 -> 0 | I5: =I3-I4 -> 0 | J5: =J3-J4 -> 0 | K5: =K3-K4 -> 0 | L5: =L3-L4 -> 0 | M5: =M3-M4 -> 0 | N5: =N3-N4 -> 0
D6: =B6*0.4 -> 0
D7: =B7*0.4 -> 0
D8: =B8*0.4 -> 0
D9: =B9*0.4 -> 0
D10: =B10*0.4 -> 0
D11: =B11*0.4 -> 0
D12: =B12*0.4 -> 0
D13: =B13*0.4 -> 0
D14: =B14*0.4 -> 0
D15: =B15*0.4 -> 0
D16: =B16*0.4 -> 0
D17: =B17*0.4 -> 0
... D256: =B256*0.4 -> 0

Sheet Вложения в компанию
A1: Клиенты | B1: Дата загрузки | C1: Оплата | D1: Вид опл | E1: За 1 перевозку | F1: За 2 перевозку | G1: Трнаспорт | H1: Дата выгрузки | I1: Клиенты | J1: Водитель | K1: Бух-док-ттн-фото | L1: срок оплаты
A2: ЙЕЛЛОУ-ГРУПП | B2: 46175 | C2: 130000 | D2: без | E2: 15000 без | G2: фура 12 | H2: 46185 | I2: Клиент ( dh-yg@bk.ru +79169759061 Данил) | J2: 79689110077
A3: Ципилев К А | B3: 46174 | C3: 140000 | D3: нал | E3: 10000 без | G3: фура 12 | H3: 46186 | I3: Клиент ( cb-pereezdov@mail.ru +79600162928 Максим) | J3: 79376007419
A4: ПАРУС | B4: 46175 | C4: 195000 | D4: ндс | E4: 17000 ндс | G4: фура 12 | H4: 46185 | I4: Клиент (log13@parustk.ru +79291923135 Юлия) | J4: 79857660480
A5: Гамилова | B5: 46176 | C5: 75000 | D5: без | E5: 8000 без | F5: 25000 без | G5: фура 12 | H5: 46206 | I5: Знаю ее
A6: Мой клиент | B6: 46177 | C6: 105000 | D6: нал | E6: 9000 без | G6: Фура 13 | H6: 46215 | I6: без почты макс
A7: К10 | B7: 46178 | C7: 150000 | D7: ндс | E7: 8000 без | G7: фура 13 | H7: 46217 | I7: клиент ( anna-maria@motlog.ru +79200619188 Анна-Мария)
A8: ООО ТЛК "ВенТранс" | B8: 46177 | C8: 90000 | D8: ндс | E8: Сама привезла | G8: фура 13 | H8: 46215 | I8: клиент ( ventrans@yandex.ru +79030934325)
A9: ООО Вип груз | B9: 46178 | C9: 185000 | D9: ндс | E9: Фура забирает | G9: фура 13 | H9: 46217 | I9: Клиент ( ipatov.vladislav@bk.ru+7 993 533-40-64 Анна )
A10: Ип Роженков И.В | B10: 46192 | C10: 125000 | D10: ндс | E10: фура забирает | G10: Фура 15 | H10: 46202 | I10: Клиент ( t079@yandex.ru ++7 920 056-73-56 Галина) | J10: фура
A11: ип Сизова Г.В | B11: 46190 | C11: 50000 | E11: 6500 без | G11: Фура 16 | H11: 46199 | I11: Клиент (ipsizova19@mail.ru +7 (915) 7519339 Галина) | J11: 79376007419
A12: Русдорзнак | B12: 46190 | C12: 95000 | D12: ндс | E12: 20000 без | F12: 6000 без | G12: фура 15 | H12: 46199 | I12: Клиент ( logist@rusdorznak.ru +7 906 301-09-73 Галина) | J12: 79678073377
A13: Экспресс-ст | B13: 46191 | C13: 80000 | D13: ндс | E13: 12000 без | F13: 6000 без | G13: фура 15 | H13: 46199 | I13: Клиент ( expressperm@bk.ru +7 912 881-00-16 Иван) | J13: 89051465560
A14: НПК | B14: 46191 | C14: 97000 | D14: ндс | E14: 21000 ндс | G14: фура 16 | H14: 46199 | I14: Клиент ( 5860456@npksm.ru+7 (953) 586-04-56 Иван | J14: 79802401370
A15: СТД Развитие | B15: 46190 | C15: 140000 | D15: ндс | E15: 25000 ндс | G15: фура 15 | H15: 46202 | I15: Клиент ( stdrazvitie@yandex.ru 7 (812) 9252660 Дмитрий | J15: 79521053645
A16: ООО АВИКАР | B16: 46190 | C16: 140000 | D16: ндс | E16: 20000 ндс | G16: фура 15 | H16: 46203 | I16: Клиент (logistavikar@mail.ru +7 965 603-25-54 | J16: Костин
A17: дл24 | B17: 46191 | C17: 47000 | D17: ндс | E17: 13000 без | G17: фура 15 | H17: 46203 | I17: Клиент ( s.kulagina@dl24.su +79612429341) | J17: 7 960 365-9599
A18: ООО Юкон Стрим | B18: 46192 | C18: 210000 | D18: ндс | E18: фура 16 | G18: фура 15 | H18: 46203 | I18: Клиент (ukonstreem@yandex.ru +7 965 059-88-05 Влидислав )
A19: ООО «ТЛК «АЗИМУТ» | B19: 46197 | C19: 250000 | D19: НДС | E19: 37000 НДС | F19: 10000 ндс | G19: ФУРА 15 | H19: 46199 | I19: Клиент (tkazimut777@yandex.ru 89010470005 Руслан) | J19: 89106917886
A20: ООО «ТЛК «АЗИМУТ» | C20: 550000 | D20: ндс | E20: фура 470000 | I20: Клиент (tkazimut777@yandex.ru 89010470005 Руслан) | J20: фура
A21: ООО «ТЛК «АЗИМУТ» | B21: 46197 | C21: 550000 | D21: ндс | E21: фура 470000 | I21: Клиент (tkazimut777@yandex.ru 89010470005 Руслан) | J21: фура
A22: Елисеев Роман Николаевич | B22: 46192 | C22: 90000 | D22: ндс | E22: 10000 без | G22: фура 16 | I22: Клиент (domobil@yandex.ru +7 965 723-37-77 Роман) | J22: 79262302876
A23: Тутубалин Д.В | B23: 46189 | C23: 75000 | D23: нал | E23: 8000 БЕЗ | G23: ФУРА 16 | I23: Клиент ( domobil@yandex.ru 7 960 096-96-80 Денис | J23: 79773948612
A24: тэк Юником Карго | B24: 46192 | C24: 50000 | D24: ндс | E24: 6000 без | G24: фура 16 | I24: Клиент (s.lobanenko@unicomtk.ru 7 925 292-32-82 Станислав | J24: 79265398809
A25: ООО «ТЛК «АЗИМУТ» | B25: 46195 | C25: 250000 | D25: ндс | E25: 30000 ндс | G25: ФУРА 17 | I25: Клиент (tkazimut777@yandex.ru 89010470005 Руслан)
A26: ИП Митяева Т.В | B26: 46196 | C26: 140000 | D26: БЕЗ | E26: 20000 БЕЗ | G26: ФУРА 17 | I26: Клиент ( 32ilya69@mail.ru +7 962 143-55-75 Илья | J26: 89268254118
A27: Лидер Тракт | B27: 46197 | C27: 75000 | D27: БЕЗ | E27: 9000 без | G27: фура 17 | H27: 46209 | I27: Клиент (a.rozhkov@lider-truck.ru 79162188302)
A28: ИП Трошина О Е | B28: 46197 | C28: 120000 | D28: БЕЗ | E28: 25000 | G28: ФУРА 17 | H28: 46209 | I28: Клиент (e.korol@agrotrans.ooo 89267098114 екатерина) | J28: 89020064044
A29: ООО ТЛК "ВенТранс" | B29: 46198 | C29: 60000 | D29: ндс | E29: Сама привезла | G29: фура 17 | H29: 03.07,2026 | I29: клиент ( ventrans@yandex.ru +79030934325)
A30: ООО «ТЛК «АЗИМУТ» | B30: 46202 | C30: 550000 | D30: ндс | E30: фура 470000 ндс | H30: 08-09.07.2026 | I30: Клиент (tkazimut777@yandex.ru 89010470005 Руслан)
A31: ООО ТК "СИБИТЭК" | B31: 46202 | C31: 70000 | D31: ндс | E31: 12000 ндс | G31: фура 18 | H31: 46211 | I31: Клиент (perevozzka138@yandex.ru +7 964 808-77-76 Ольга) | J31: 7 926 357-86-09
A32: ООО ТК "СИБИТЭК" | B32: 46203 | C32: 45000 | D32: без | E32: 5000 без | G32: фура 18 | I32: Клиент (perevozzka138@yandex.ru +7 964 808-77-76 Ольга) | J32: =7906757-41-95 -> 7906621
A33: ООО ТД АртТекс | B33: 46204 | C33: 85000 | D33: без | E33: 10000 без | G33: фура 18 | I33: Клиент (zua@art-tex37.ru +7 980 686-90-77 Юлья) | J33: 7(916)-657-36-23
A34: Дельта | B34: 46206 | C34: 200000 | D34: без | E34: 19000 без | G34: фура 18 | H34: 46216 | I34: Клиент(logistic@bkdelta.ru Дальмя в Максе ) | J34: 7 925 022-90-21
A35: ТЭК Глобал логистик Ямал | B35: 46205 | C35: 30000 | D35: без | E35: сам привезет | G35: фура 18 | H35: 46216 | I35: Клиент( logist.2@bk.ruДанил+7 (932) 0505101)
A36: СТК СИРИУССТРОЙ | B36: 46205 | C36: 75000 | D36: без | E36: 8500 БЕЗ | G36: ФУРА 18 | H36: 46216 | I36: Клиент(logist@ir-mash.ru8-964-281-44-85 ОЛЬГА) | J36: 89202650203
A37: Мой клиент константин | B37: 46217 | C37: 195000 без | D37: без | E37: 35000 без | G37: фура 21 | H37: Без заявки | I37: клиент костя 89146384325 | J37: 7 908 300-30-35
A38: Взлет | B38: 46224 | C38: 300000 | D38: ндс | E38: 33000 без | G38: фура 21 | H38: 46234 | I38: Клиент (vefremova@vztr.ru +7 911 180-43-80 ВИОЛЕТА )
A39: ООО ТЛК "ВенТранс" | B39: 46224 | C39: 30000 | D39: ндс | E39: Сама привезла | G39: фура 21 | H39: 46234 | I39: Клиент ( ventrans@yandex.ru
A40: ООО ТЛК "ВенТранс" | B40: 46224 | C40: 55000 | D40: ндс | E40: Сама привезла | G40: фура 22 | H40: 46244 | I40: Клиент (vefremova@vztr.ru +7 911 180-43-80 ВИОЛЕТА )
...

Sheet Прибыль
A1: Прибыль компании
A2: Оплаченные суммы фуры | B2: Оплаченные суммы пр. Расходы | C2: Сотрудники | D2: Аренда | E2: Сотовая связь | F2: Остальные расходы | G2: ЦРМ Система
A3: ='Расходы на перевозки'!AE1 -> 0 | B3: ='Расходы на перевозки'!AG1 -> 0 | C3: =SUM('Зарплаты '!H3:N3) -> 0 | F3: =SUM('Вложения в компанию'!F:F) -> 0
A5: Дельта прибыль: | B5: Общее число расходов: | C5: Итог:
A6: ='Расходы на перевозки'!Y1 -> 103773 | B6: =SUM(3:3) -> 0 | C6: =A6-B6 -> 103773
